<?xml version="1.0" ?>
<robot name="panda">
  <!-- sub-link defining detailed meshes for collision with environment -->
  <link name="panda_link0">
      <inertial>
        <origin xyz="-0.041018 -0.00014 0.049974" rpy="0 0 0"/>
        <mass value="0.629769"/>
        <inertia
          ixx="0.00315" iyy="0.00388" izz="0.004285"
          ixy="8.2904e-7" ixz="0.00015" iyz="8.2299e-6"/>
    </inertial>
    <visual>
      <geometry>
        <mesh filename="file:///home/paulav/contact_ws/src/franka_ros/franka_description/meshes/visual/link0.dae"/>
      </geometry>
    </visual>
    <collision>
      <geometry>
        <mesh filename="file:///home/paulav/contact_ws/src/franka_ros/franka_description/meshes/collision/link0.stl"/>
      </geometry>
    </collision>
  </link>
  <!-- sub-link defining coarse geometries of real robot's internal self-collision -->
  <link name="panda_link0_sc">
    <collision>
      <origin rpy="0 1.5707963267948966 0" xyz="-0.075 0 0.06"/>
      <geometry>
        <cylinder length="0.03" radius="0.09"/>
      </geometry>
    </collision>
    <collision>
      <origin xyz="-0.06 0 0.06"/>
      <geometry>
        <sphere radius="0.09"/>
      </geometry>
    </collision>
    <collision>
      <origin xyz="-0.09 0 0.06"/>
      <geometry>
        <sphere radius="0.09"/>
      </geometry>
    </collision>
  </link>
  <!-- fixed joint between both sub-links -->
  <joint name="panda_link0_sc_joint" type="fixed">
    <origin rpy="0 0 0"/>
    <parent link="panda_link0"/>
    <child link="panda_link0_sc"/>
  </joint>
  <!-- sub-link defining detailed meshes for collision with environment -->
  <link name="panda_link1">
    <inertial>
      <origin xyz="0.003875 0.002081 -0.04762" rpy="0 0 0"/>
      <mass value="4.970684"/>
      <inertia
        ixx="0.70337" iyy="0.70661" izz="0.0091170"
        ixy="-0.00013900" ixz="0.0067720" iyz="0.019169"/>
    </inertial>
    <visual>
      <geometry>
        <mesh filename="file:///home/paulav/contact_ws/src/franka_ros/franka_description/meshes/visual/link1.dae"/>
      </geometry>
    </visual>
    <collision>
      <geometry>
        <mesh filename="file:///home/paulav/contact_ws/src/franka_ros/franka_description/meshes/collision/link1.stl"/>
      </geometry>
    </collision>
  </link>
  <!-- sub-link defining coarse geometries of real robot's internal self-collision -->
  <link name="panda_link1_sc">
    <collision>
      <origin rpy="0 0 0" xyz="0 0 -0.1915"/>
      <geometry>
        <cylinder length="0.283" radius="0.09"/>
      </geometry>
    </collision>
    <collision>
      <origin xyz="0 0 -0.05000000000000002"/>
      <geometry>
        <sphere radius="0.09"/>
      </geometry>
    </collision>
    <collision>
      <origin xyz="0 0 -0.33299999999999996"/>
      <geometry>
        <sphere radius="0.09"/>
      </geometry>
    </collision>
  </link>
  <!-- fixed joint between both sub-links -->
  <joint name="panda_link1_sc_joint" type="fixed">
    <origin rpy="0 0 0"/>
    <parent link="panda_link1"/>
    <child link="panda_link1_sc"/>
  </joint>
  <joint name="panda_joint1" type="revolute">
    <origin rpy="0 0 0" xyz="0 0 0.333"/>
    <parent link="panda_link0"/>
    <child link="panda_link1"/>
    <axis xyz="0 0 1"/>
    <limit effort="87.0" lower="-2.8973" upper="2.8973" velocity="2.175"/>
    <safety_controller k_position="100.0" k_velocity="40.0" soft_lower_limit="-2.8973" soft_upper_limit="2.8973"/>
    <dynamics D="1" K="7000" damping="0.003" friction="0.0" mu_coulomb="0" mu_viscous="16"/>
  </joint>
  <!-- sub-link defining detailed meshes for collision with environment -->
  <link name="panda_link2">
    <inertial>
      <origin xyz="-0.003141 -0.02872 0.003495" rpy="0 0 0"/>
      <mass value="0.646926"/>
      <inertia
        ixx="0.0079620" iyy="2.8110e-2" izz="2.5995e-2"
        ixy="-3.925e-3" ixz="1.0254e-2" iyz="7.04e-4"/>
    </inertial>
    <visual>
      <geometry>
        <mesh filename="file:///home/paulav/contact_ws/src/franka_ros/franka_description/meshes/visual/link2.dae"/>
      </geometry>
    </visual>
    <collision>
      <geometry>
        <mesh filename="file:///home/paulav/contact_ws/src/franka_ros/franka_description/meshes/collision/link2.stl"/>
      </geometry>
    </collision>
  </link>
  <!-- sub-link defining coarse geometries of real robot's internal self-collision -->
  <link name="panda_link2_sc">
    <collision>
      <origin rpy="0 0 0" xyz="0 0 0"/>
      <geometry>
        <cylinder length="0.12" radius="0.09"/>
      </geometry>
    </collision>
    <collision>
      <origin xyz="0 0 0.06"/>
      <geometry>
        <sphere radius="0.09"/>
      </geometry>
    </collision>
    <collision>
      <origin xyz="0 0 -0.06"/>
      <geometry>
        <sphere radius="0.09"/>
      </geometry>
    </collision>
  </link>
  <!-- fixed joint between both sub-links -->
  <joint name="panda_link2_sc_joint" type="fixed">
    <origin rpy="0 0 0"/>
    <parent link="panda_link2"/>
    <child link="panda_link2_sc"/>
  </joint>
  <joint name="panda_joint2" type="revolute">
    <origin rpy="-1.5707963267948966 0 0" xyz="0 0 0"/>
    <parent link="panda_link1"/>
    <child link="panda_link2"/>
    <axis xyz="0 0 1"/>
    <limit effort="87.0" lower="-1.7628" upper="1.7628" velocity="2.175"/>
    <safety_controller k_position="100.0" k_velocity="40.0" soft_lower_limit="-1.7628" soft_upper_limit="1.7628"/>
    <dynamics D="1" K="7000" damping="0.003" friction="0.0" mu_coulomb="0" mu_viscous="16"/>
  </joint>
  <!-- sub-link defining detailed meshes for collision with environment -->
  <link name="panda_link3">
    <inertial>
      <origin xyz="2.7518e-2 3.9252e-2 -6.6502e-2" rpy="0 0 0"/>
      <mass value="3.228604"/>
      <inertia
        ixx="3.7242e-2" iyy="3.6155e-2" izz="1.083e-2"
        ixy="-4.761e-3" ixz="-1.1396e-2" iyz="-1.2805e-2"/>
    </inertial>
    <visual>
      <geometry>
        <mesh filename="file:///home/paulav/contact_ws/src/franka_ros/franka_description/meshes/visual/link3.dae"/>
      </geometry>
    </visual>
    <collision>
      <geometry>
        <mesh filename="file:///home/paulav/contact_ws/src/franka_ros/franka_description/meshes/collision/link3.stl"/>
      </geometry>
    </collision>
  </link>
  <!-- sub-link defining coarse geometries of real robot's internal self-collision -->
  <link name="panda_link3_sc">
    <collision>
      <origin rpy="0 0 0" xyz="0 0 -0.145"/>
      <geometry>
        <cylinder length="0.15" radius="0.09"/>
      </geometry>
    </collision>
    <collision>
      <origin xyz="0 0 -0.06999999999999999"/>
      <geometry>
        <sphere radius="0.09"/>
      </geometry>
    </collision>
    <collision>
      <origin xyz="0 0 -0.21999999999999997"/>
      <geometry>
        <sphere radius="0.09"/>
      </geometry>
    </collision>
  </link>
  <!-- fixed joint between both sub-links -->
  <joint name="panda_link3_sc_joint" type="fixed">
    <origin rpy="0 0 0"/>
    <parent link="panda_link3"/>
    <child link="panda_link3_sc"/>
  </joint>
  <joint name="panda_joint3" type="revolute">
    <origin rpy="1.5707963267948966 0 0" xyz="0 -0.316 0"/>
    <parent link="panda_link2"/>
    <child link="panda_link3"/>
    <axis xyz="0 0 1"/>
    <limit effort="87.0" lower="-2.8973" upper="2.8973" velocity="2.175"/>
    <safety_controller k_position="100.0" k_velocity="40.0" soft_lower_limit="-2.8973" soft_upper_limit="2.8973"/>
    <dynamics D="1" K="7000" damping="0.003" friction="0.0" mu_coulomb="0" mu_viscous="16"/>
  </joint>
  <!-- sub-link defining detailed meshes for collision with environment -->
  <link name="panda_link4">
    <inertial>
      <origin xyz="-5.317e-2 1.04419e-1 2.7454e-2" rpy="0 0 0"/>
      <mass value="3.587895"/>
      <inertia
        ixx="2.5853e-2" iyy="1.9552e-2" izz="2.8323e-2"
        ixy="7.796e-3" ixz="-1.332e-3" iyz="8.641e-3"/>
    </inertial>
    <visual>
      <geometry>
        <mesh filename="file:///home/paulav/contact_ws/src/franka_ros/franka_description/meshes/visual/link4.dae"/>
      </geometry>
    </visual>
    <collision>
      <geometry>
        <mesh filename="file:///home/paulav/contact_ws/src/franka_ros/franka_description/meshes/collision/link4.stl"/>
      </geometry>
    </collision>
  </link>
  <!-- sub-link defining coarse geometries of real robot's internal self-collision -->
  <link name="panda_link4_sc">
    <collision>
      <origin rpy="0 0 0" xyz="0 0 0"/>
      <geometry>
        <cylinder length="0.12" radius="0.09"/>
      </geometry>
    </collision>
    <collision>
      <origin xyz="0 0 0.06"/>
      <geometry>
        <sphere radius="0.09"/>
      </geometry>
    </collision>
    <collision>
      <origin xyz="0 0 -0.06"/>
      <geometry>
        <sphere radius="0.09"/>
      </geometry>
    </collision>
  </link>
  <!-- fixed joint between both sub-links -->
  <joint name="panda_link4_sc_joint" type="fixed">
    <origin rpy="0 0 0"/>
    <parent link="panda_link4"/>
    <child link="panda_link4_sc"/>
  </joint>
  <joint name="panda_joint4" type="revolute">
    <origin rpy="1.5707963267948966 0 0" xyz="0.0825 0 0"/>
    <parent link="panda_link3"/>
    <child link="panda_link4"/>
    <axis xyz="0 0 1"/>
    <limit effort="87.0" lower="-3.0718" upper="-0.0698" velocity="2.175"/>
    <safety_controller k_position="100.0" k_velocity="40.0" soft_lower_limit="-3.0718" soft_upper_limit="-0.0698"/>
    <dynamics D="1" K="7000" damping="0.003" friction="0.0" mu_coulomb="0" mu_viscous="16"/>
  </joint>
  <!-- sub-link defining detailed meshes for collision with environment -->
  <link name="panda_link5">
    <inertial>
      <origin xyz="-1.1953e-2 4.1065e-2 -3.8437e-2" rpy="0 0 0"/>
      <mass value="1.225946"/>
      <inertia
        ixx="3.5549e-2" iyy="2.9474e-2" izz="8.627e-3"
        ixy="-2.117e-3" ixz="-4.037e-3" iyz="2.29e-4"/>
    </inertial>
    <visual>
      <geometry>
        <mesh filename="file:///home/paulav/contact_ws/src/franka_ros/franka_description/meshes/visual/link5.dae"/>
      </geometry>
    </visual>
    <collision>
      <geometry>
        <mesh filename="file:///home/paulav/contact_ws/src/franka_ros/franka_description/meshes/collision/link5.stl"/>
      </geometry>
    </collision>
  </link>
  <!-- sub-link defining coarse geometries of real robot's internal self-collision -->
  <link name="panda_link5_sc">
    <collision>
      <origin rpy="0 0 0" xyz="0 0 -0.26"/>
      <geometry>
        <cylinder length="0.1" radius="0.09"/>
      </geometry>
    </collision>
    <collision>
      <origin xyz="0 0 -0.21000000000000002"/>
      <geometry>
        <sphere radius="0.09"/>
      </geometry>
    </collision>
    <collision>
      <origin xyz="0 0 -0.31"/>
      <geometry>
        <sphere radius="0.09"/>
      </geometry>
    </collision>
    <collision>
      <origin rpy="0 0 0.08" xyz="0 0.08 -0.13"/>
      <geometry>
        <cylinder length="0.14" radius="0.055"/>
      </geometry>
    </collision>
    <collision>
      <origin xyz="0 0.08 -0.06"/>
      <geometry>
        <sphere radius="0.055"/>
      </geometry>
    </collision>
    <collision>
      <origin xyz="0 0.08 -0.2"/>
      <geometry>
        <sphere radius="0.055"/>
      </geometry>
    </collision>
  </link>
  <!-- fixed joint between both sub-links -->
  <joint name="panda_link5_sc_joint" type="fixed">
    <origin rpy="0 0 0"/>
    <parent link="panda_link5"/>
    <child link="panda_link5_sc"/>
  </joint>
  <joint name="panda_joint5" type="revolute">
    <origin rpy="-1.5707963267948966 0 0" xyz="-0.0825 0.384 0"/>
    <parent link="panda_link4"/>
    <child link="panda_link5"/>
    <axis xyz="0 0 1"/>
    <limit effort="12.0" lower="-2.8973" upper="2.8973" velocity="2.61"/>
    <safety_controller k_position="100.0" k_velocity="40.0" soft_lower_limit="-2.8973" soft_upper_limit="2.8973"/>
    <dynamics D="1" K="7000" damping="0.003" friction="0.0" mu_coulomb="0" mu_viscous="16"/>
  </joint>
  <!-- sub-link defining detailed meshes for collision with environment -->
  <link name="panda_link6">
    <inertial>
      <origin xyz="6.0149e-2 -1.4117e-2 -1.0517e-2" rpy="0 0 0"/>
      <mass value="1.666555"/>
      <inertia
        ixx="1.964e-3" iyy="4.354e-3" izz="5.433e-3"
        ixy="1.09e-4" ixz="-1.158e-3" iyz="3.41e-4"/>
    </inertial>
    <visual>
      <geometry>
        <mesh filename="file:///home/paulav/contact_ws/src/franka_ros/franka_description/meshes/visual/link6.dae"/>
      </geometry>
    </visual>
    <collision>
      <geometry>
        <mesh filename="file:///home/paulav/contact_ws/src/franka_ros/franka_description/meshes/collision/link6.stl"/>
      </geometry>
    </collision>
  </link>
  <!-- sub-link defining coarse geometries of real robot's internal self-collision -->
  <link name="panda_link6_sc">
    <collision>
      <origin rpy="0 0 0" xyz="0 0 -0.03"/>
      <geometry>
        <cylinder length="0.08" radius="0.08"/>
      </geometry>
    </collision>
    <collision>
      <origin xyz="0 0 0.010000000000000002"/>
      <geometry>
        <sphere radius="0.08"/>
      </geometry>
    </collision>
    <collision>
      <origin xyz="0 0 -0.07"/>
      <geometry>
        <sphere radius="0.08"/>
      </geometry>
    </collision>
  </link>
  <!-- fixed joint between both sub-links -->
  <joint name="panda_link6_sc_joint" type="fixed">
    <origin rpy="0 0 0"/>
    <parent link="panda_link6"/>
    <child link="panda_link6_sc"/>
  </joint>
  <joint name="panda_joint6" type="revolute">
    <origin rpy="1.5707963267948966 0 0" xyz="0 0 0"/>
    <parent link="panda_link5"/>
    <child link="panda_link6"/>
    <axis xyz="0 0 1"/>
    <limit effort="12.0" lower="-0.0175" upper="3.7525" velocity="2.61"/>
    <safety_controller k_position="100.0" k_velocity="40.0" soft_lower_limit="-0.0175" soft_upper_limit="3.7525"/>
    <dynamics D="1" K="7000" damping="0.003" friction="0.0" mu_coulomb="0" mu_viscous="16"/>
  </joint>
  <!-- sub-link defining detailed meshes for collision with environment -->
  <link name="panda_link7">
    <inertial>
      <origin xyz="1.0517e-2 -4.252e-3 6.1597e-2" rpy="0 0 0"/>
      <mass value="7.35522e-01"/>
      <inertia
        ixx="1.2516e-2" iyy="1.0027e-2" izz="4.815e-3"
        ixy="-4.28e-4" ixz="-1.196e-3" iyz="-7.41e-4"/>
    </inertial>
    <visual>
      <geometry>
        <mesh filename="file:///home/paulav/contact_ws/src/franka_ros/franka_description/meshes/visual/link7.dae"/>
      </geometry>
    </visual>
    <collision>
      <geometry>
        <mesh filename="file:///home/paulav/contact_ws/src/franka_ros/franka_description/meshes/collision/link7.stl"/>
      </geometry>
    </collision>
  </link>
  <!-- sub-link defining coarse geometries of real robot's internal self-collision -->
  <link name="panda_link7_sc">
    <collision>
      <origin rpy="0 0 0" xyz="0 0 0.01"/>
      <geometry>
        <cylinder length="0.14" radius="0.07"/>
      </geometry>
    </collision>
    <collision>
      <origin xyz="0 0 0.08"/>
      <geometry>
        <sphere radius="0.07"/>
      </geometry>
    </collision>
    <collision>
      <origin xyz="0 0 -0.060000000000000005"/>
      <geometry>
        <sphere radius="0.07"/>
      </geometry>
    </collision>
    <collision>
      <origin rpy="0 1.5707963267948966 0" xyz="0.06 0 0.082"/>
      <geometry>
        <cylinder length="0.01" radius="0.06"/>
      </geometry>
    </collision>
    <collision>
      <origin xyz="0.065 0 0.082"/>
      <geometry>
        <sphere radius="0.06"/>
      </geometry>
    </collision>
    <collision>
      <origin xyz="0.055 0 0.082"/>
      <geometry>
        <sphere radius="0.06"/>
      </geometry>
    </collision>
  </link>
  <!-- fixed joint between both sub-links -->
  <joint name="panda_link7_sc_joint" type="fixed">
    <origin rpy="0 0 0.7853981633974483"/>
    <parent link="panda_link7"/>
    <child link="panda_link7_sc"/>
  </joint>
  <joint name="panda_joint7" type="revolute">
    <origin rpy="1.5707963267948966 0 0" xyz="0.088 0 0"/>
    <parent link="panda_link6"/>
    <child link="panda_link7"/>
    <axis xyz="0 0 1"/>
    <limit effort="12.0" lower="-2.8973" upper="2.8973" velocity="2.61"/>
    <safety_controller k_position="100.0" k_velocity="40.0" soft_lower_limit="-2.8973" soft_upper_limit="2.8973"/>
    <dynamics D="1" K="7000" damping="0.003" friction="0.0" mu_coulomb="0" mu_viscous="16"/>
  </joint>
 <!-- <link name="panda_link8"/>
  <joint name="panda_joint8" type="fixed">
    <origin rpy="0 0 0" xyz="0 0 0.107"/>
    <parent link="panda_link7"/>
    <child link="panda_link8"/>
  </joint> --> 
<link name="peg">
  <inertial>
    <origin xyz="0 0 0.0785" rpy="0 0 0"/>
    <mass value="0.3"/>
    <!-- keep your current inertia for now unless MuJoCo provides full values -->
    <inertia ixx="0.0001" iyy="0.0001" izz="0.0001"
             ixy="0" ixz="0" iyz="0"/>
  </inertial>
  <visual>
    <origin xyz="0 0 0" rpy="0 0 0"/>
    <geometry>
      <mesh filename="/home/paulav/contact_ws/src/assets/peg.obj"/>
    </geometry>
  </visual>
  <collision>
    <origin xyz="0 0 0" rpy="0 0 0"/>
    <geometry>
      <mesh filename="/home/paulav/contact_ws/src/assets/peg.stl"/>
    </geometry>
  </collision>
</link>

<joint name="peg_fixed" type="fixed">
  <parent link="panda_link7"/>
  <child link="peg"/>
  <origin xyz="0 0 0.107" rpy="0 0 0"/>
</joint>

</robot>
